<?xml version="1.0" encoding="UTF-8"?>
<testng-results skipped="0" failed="1" ignored="4" total="5" passed="0">
  <reporter-output>
  </reporter-output>
  <suite name="Default suite" duration-ms="16233" started-at="2018-11-21T16:28:26Z" finished-at="2018-11-21T16:28:42Z">
    <groups>
    </groups>
    <test name="Default test" duration-ms="16233" started-at="2018-11-21T16:28:26Z" finished-at="2018-11-21T16:28:42Z">
      <class name="Tests.login.LoginTest">
        <test-method status="PASS" signature="beforeClass()[pri:0, instance:Tests.login.LoginTest@5b275dab]" name="beforeClass" is-config="true" duration-ms="12463" started-at="2018-11-21T16:28:26Z" finished-at="2018-11-21T16:28:38Z">
          <reporter-output>
          </reporter-output>
        </test-method> <!-- beforeClass -->
        <test-method status="PASS" signature="beforeMethod()[pri:0, instance:Tests.login.LoginTest@5b275dab]" name="beforeMethod" is-config="true" duration-ms="615" started-at="2018-11-21T16:28:38Z" finished-at="2018-11-21T16:28:39Z">
          <reporter-output>
          </reporter-output>
        </test-method> <!-- beforeMethod -->
        <test-method status="FAIL" signature="TC05()[pri:0, instance:Tests.login.LoginTest@5b275dab]" name="TC05" duration-ms="2579" started-at="2018-11-21T16:28:39Z" description="TC05 - System shows message when user enters wrong password several times" finished-at="2018-11-21T16:28:41Z">
          <exception class="java.lang.AssertionError">
            <message>
              <![CDATA[Message should be You have used 4 out of 5 login attempts. After all 5 have been used, you will be unable to login for 15 minutes. expected [You have used 4 out of 5 login attempts. After all 5 have been used, you will be unable to login for 15 minutes.] but found [There was a problem with your login and/or errors exist in your form.]]]>
            </message>
            <full-stacktrace>
              <![CDATA[java.lang.AssertionError: Message should be You have used 4 out of 5 login attempts. After all 5 have been used, you will be unable to login for 15 minutes. expected [You have used 4 out of 5 login attempts. After all 5 have been used, you will be unable to login for 15 minutes.] but found [There was a problem with your login and/or errors exist in your form.]
at org.testng.Assert.fail(Assert.java:96)
at org.testng.Assert.failNotEquals(Assert.java:776)
at org.testng.Assert.assertEqualsImpl(Assert.java:137)
at org.testng.Assert.assertEquals(Assert.java:118)
at org.testng.Assert.assertEquals(Assert.java:453)
at Tests.login.LoginTest.TC05(LoginTest.java:87)
at sun.reflect.NativeMethodAccessorImpl.invoke0(Native Method)
at sun.reflect.NativeMethodAccessorImpl.invoke(Unknown Source)
at sun.reflect.DelegatingMethodAccessorImpl.invoke(Unknown Source)
at java.lang.reflect.Method.invoke(Unknown Source)
at org.testng.internal.MethodInvocationHelper.invokeMethod(MethodInvocationHelper.java:124)
at org.testng.internal.Invoker.invokeMethod(Invoker.java:580)
at org.testng.internal.Invoker.invokeTestMethod(Invoker.java:716)
at org.testng.internal.Invoker.invokeTestMethods(Invoker.java:988)
at org.testng.internal.TestMethodWorker.invokeTestMethods(TestMethodWorker.java:125)
at org.testng.internal.TestMethodWorker.run(TestMethodWorker.java:109)
at org.testng.TestRunner.privateRun(TestRunner.java:648)
at org.testng.TestRunner.run(TestRunner.java:505)
at org.testng.SuiteRunner.runTest(SuiteRunner.java:455)
at org.testng.SuiteRunner.runSequentially(SuiteRunner.java:450)
at org.testng.SuiteRunner.privateRun(SuiteRunner.java:415)
at org.testng.SuiteRunner.run(SuiteRunner.java:364)
at org.testng.SuiteRunnerWorker.runSuite(SuiteRunnerWorker.java:52)
at org.testng.SuiteRunnerWorker.run(SuiteRunnerWorker.java:84)
at org.testng.TestNG.runSuitesSequentially(TestNG.java:1208)
at org.testng.TestNG.runSuitesLocally(TestNG.java:1137)
at org.testng.TestNG.runSuites(TestNG.java:1049)
at org.testng.TestNG.run(TestNG.java:1017)
at org.testng.remote.AbstractRemoteTestNG.run(AbstractRemoteTestNG.java:114)
at org.testng.remote.RemoteTestNG.initAndRun(RemoteTestNG.java:251)
at org.testng.remote.RemoteTestNG.main(RemoteTestNG.java:77)
]]>
            </full-stacktrace>
          </exception> <!-- java.lang.AssertionError -->
          <reporter-output>
          </reporter-output>
        </test-method> <!-- TC05 -->
        <test-method status="PASS" signature="afterClass()[pri:0, instance:Tests.login.LoginTest@5b275dab]" name="afterClass" is-config="true" duration-ms="550" started-at="2018-11-21T16:28:41Z" finished-at="2018-11-21T16:28:42Z">
          <reporter-output>
          </reporter-output>
        </test-method> <!-- afterClass -->
        <test-method status="PASS" signature="afterMethod()[pri:0, instance:Tests.login.LoginTest@5b275dab]" name="afterMethod" is-config="true" duration-ms="0" started-at="2018-11-21T16:28:41Z" finished-at="2018-11-21T16:28:41Z">
          <reporter-output>
          </reporter-output>
        </test-method> <!-- afterMethod -->
      </class> <!-- Tests.login.LoginTest -->
    </test> <!-- Default test -->
  </suite> <!-- Default suite -->
</testng-results>
